Workbook

Sheet Training_Data
A1: Sample_ID | B1: H2 | C1: CH4 | D1: C2H6 | E1: C2H4 | F1: C2H2 | G1: CO | H1: CO2 | I1: H2_Score | J1: CH4_Score | K1: C2H6_Score | L1: C2H4_Score | M1: C2H2_Score | N1: CO_Score | O1: CO2_Score | P1: HI | Q1: Condition | R1: Binary_HI | S1: Rule_Check
A2: SYN-00001 | B2: 15.576 | C2: 90.537 | D2: 18.372 | E2: 9.128 | F2: 0.147 | G2: 263.772 | H2: 1420.246 | I2: =ROUND(IF(B2<=Thresholds!$B$2,1-(B2/Thresholds!$B$2)*0.24,IF(B2<=Thresholds!$D$2,0.75-((B2-Thresholds!$C$2)/(Thresholds!$D$2-Thresholds!$C$2))*0.249,IF(B2<=Thresholds!$F$2,0.499-((B2-Thresholds!$E$2)/(Thresholds!$F$2-Thresholds!$E$2))*0.279,MAX(0.02,0.2-((B2-Thresholds!$G$2)/(Thresholds!$H$2-Thresholds!$G$2))*0.18)))),3) -> 0.963 | J2: =ROUND(IF(C2<=Thresholds!$B$3,1-(C2/Thresholds!$B$3)*0.24,IF(C2<=Thresholds!$D$3,0.75-((C2-Thresholds!$C$3)/(Thresholds!$D$3-Thresholds!$C$3))*0.249,IF(C2<=Thresholds!$F$3,0.499-((C2-Thresholds!$E$3)/(Thresholds!$F$3-Thresholds!$E$3))*0.279,MAX(0.02,0.2-((C2-Thresholds!$G$3)/(Thresholds!$H$3-Thresholds!$G$3))*0.18)))),3) -> 0.819 | K2: =ROUND(IF(D2<=Thresholds!$B$4,1-(D2/Thresholds!$B$4)*0.24,IF(D2<=Thresholds!$D$4,0.75-((D2-Thresholds!$C$4)/(Thresholds!$D$4-Thresholds!$C$4))*0.249,IF(D2<=Thresholds!$F$4,0.499-((D2-Thresholds!$E$4)/(Thresholds!$F$4-Thresholds!$E$4))*0.279,MAX(0.02,0.2-((D2-Thresholds!$G$4)/(Thresholds!$H$4-Thresholds!$G$4))*0.18)))),3) -> 0.932 | L2: =ROUND(IF(E2<=Thresholds!$B$5,1-(E2/Thresholds!$B$5)*0.24,IF(E2<=Thresholds!$D$5,0.75-((E2-Thresholds!$C$5)/(Thresholds!$D$5-Thresholds!$C$5))*0.249,IF(E2<=Thresholds!$F$5,0.499-((E2-Thresholds!$E$5)/(Thresholds!$F$5-Thresholds!$E$5))*0.279,MAX(0.02,0.2-((E2-Thresholds!$G$5)/(Thresholds!$H$5-Thresholds!$G$5))*0.18)))),3) -> 0.956 | M2: =ROUND(IF(F2<=Thresholds!$B$6,1-(F2/Thresholds!$B$6)*0.24,IF(F2<=Thresholds!$D$6,0.75-((F2-Thresholds!$C$6)/(Thresholds!$D$6-Thresholds!$C$6))*0.249,IF(F2<=Thresholds!$F$6,0.499-((F2-Thresholds!$E$6)/(Thresholds!$F$6-Thresholds!$E$6))*0.279,MAX(0.02,0.2-((F2-Thresholds!$G$6)/(Thresholds!$H$6-Thresholds!$G$6))*0.18)))),3) -> 0.965 | N2: =ROUND(IF(G2<=Thresholds!$B$7,1-(G2/Thresholds!$B$7)*0.24,IF(G2<=Thresholds!$D$7,0.75-((G2-Thresholds!$C$7)/(Thresholds!$D$7-Thresholds!$C$7))*0.249,IF(G2<=Thresholds!$F$7,0.499-((G2-Thresholds!$E$7)/(Thresholds!$F$7-Thresholds!$E$7))*0.279,MAX(0.02,0.2-((G2-Thresholds!$G$7)/(Thresholds!$H$7-Thresholds!$G$7))*0.18)))),3) -> 0.819 | O2: =ROUND(IF(H2<=Thresholds!$B$8,1-(H2/Thresholds!$B$8)*0.24,IF(H2<=Thresholds!$D$8,0.75-((H2-Thresholds!$C$8)/(Thresholds!$D$8-Thresholds!$C$8))*0.249,IF(H2<=Thresholds!$F$8,0.499-((H2-Thresholds!$E$8)/(Thresholds!$F$8-Thresholds!$E$8))*0.279,MAX(0.02,0.2-((H2-Thresholds!$G$8)/(Thresholds!$H$8-Thresholds!$G$8))*0.18)))),3) -> 0.864 | P2: =ROUND(MIN(I2:O2),3) -> 0.819 | Q2: =IF(P2>=0.751,"Healthy",IF(P2>=0.501,"Moderate",IF(P2>=0.201,"Poor","Critical"))) -> Healthy | R2: =IF(P2>=0.5,1,0) -> 1 | S2: =IF(AND(F2>=10,F2<=35,P2>0.5),"ERROR_C2H2_POOR_CAP","OK") -> OK
A3: SYN-00002 | B3: 45.083 | C3: 9.397 | D3: 16.751 | E3: 26.504 | F3: 5.364 | G3: 528.265 | H3: 1668.476 | I3: =ROUND(IF(B3<=Thresholds!$B$2,1-(B3/Thresholds!$B$2)*0.24,IF(B3<=Thresholds!$D$2,0.75-((B3-Thresholds!$C$2)/(Thresholds!$D$2-Thresholds!$C$2))*0.249,IF(B3<=Thresholds!$F$2,0.499-((B3-Thresholds!$E$2)/(Thresholds!$F$2-Thresholds!$E$2))*0.279,MAX(0.02,0.2-((B3-Thresholds!$G$2)/(Thresholds!$H$2-Thresholds!$G$2))*0.18)))),3) -> 0.892 | J3: =ROUND(IF(C3<=Thresholds!$B$3,1-(C3/Thresholds!$B$3)*0.24,IF(C3<=Thresholds!$D$3,0.75-((C3-Thresholds!$C$3)/(Thresholds!$D$3-Thresholds!$C$3))*0.249,IF(C3<=Thresholds!$F$3,0.499-((C3-Thresholds!$E$3)/(Thresholds!$F$3-Thresholds!$E$3))*0.279,MAX(0.02,0.2-((C3-Thresholds!$G$3)/(Thresholds!$H$3-Thresholds!$G$3))*0.18)))),3) -> 0.981 | K3: =ROUND(IF(D3<=Thresholds!$B$4,1-(D3/Thresholds!$B$4)*0.24,IF(D3<=Thresholds!$D$4,0.75-((D3-Thresholds!$C$4)/(Thresholds!$D$4-Thresholds!$C$4))*0.249,IF(D3<=Thresholds!$F$4,0.499-((D3-Thresholds!$E$4)/(Thresholds!$F$4-Thresholds!$E$4))*0.279,MAX(0.02,0.2-((D3-Thresholds!$G$4)/(Thresholds!$H$4-Thresholds!$G$4))*0.18)))),3) -> 0.938 | L3: =ROUND(IF(E3<=Thresholds!$B$5,1-(E3/Thresholds!$B$5)*0.24,IF(E3<=Thresholds!$D$5,0.75-((E3-Thresholds!$C$5)/(Thresholds!$D$5-Thresholds!$C$5))*0.249,IF(E3<=Thresholds!$F$5,0.499-((E3-Thresholds!$E$5)/(Thresholds!$F$5-Thresholds!$E$5))*0.279,MAX(0.02,0.2-((E3-Thresholds!$G$5)/(Thresholds!$H$5-Thresholds!$G$5))*0.18)))),3) -> 0.873 | M3: =ROUND(IF(F3<=Thresholds!$B$6,1-(F3/Thresholds!$B$6)*0.24,IF(F3<=Thresholds!$D$6,0.75-((F3-Thresholds!$C$6)/(Thresholds!$D$6-Thresholds!$C$6))*0.249,IF(F3<=Thresholds!$F$6,0.499-((F3-Thresholds!$E$6)/(Thresholds!$F$6-Thresholds!$E$6))*0.279,MAX(0.02,0.2-((F3-Thresholds!$G$6)/(Thresholds!$H$6-Thresholds!$G$6))*0.18)))),3) -> 0.614 | N3: =ROUND(IF(G3<=Thresholds!$B$7,1-(G3/Thresholds!$B$7)*0.24,IF(G3<=Thresholds!$D$7,0.75-((G3-Thresholds!$C$7)/(Thresholds!$D$7-Thresholds!$C$7))*0.249,IF(G3<=Thresholds!$F$7,0.499-((G3-Thresholds!$E$7)/(Thresholds!$F$7-Thresholds!$E$7))*0.279,MAX(0.02,0.2-((G3-Thresholds!$G$7)/(Thresholds!$H$7-Thresholds!$G$7))*0.18)))),3) -> 0.548 | O3: =ROUND(IF(H3<=Thresholds!$B$8,1-(H3/Thresholds!$B$8)*0.24,IF(H3<=Thresholds!$D$8,0.75-((H3-Thresholds!$C$8)/(Thresholds!$D$8-Thresholds!$C$8))*0.249,IF(H3<=Thresholds!$F$8,0.499-((H3-Thresholds!$E$8)/(Thresholds!$F$8-Thresholds!$E$8))*0.279,MAX(0.02,0.2-((H3-Thresholds!$G$8)/(Thresholds!$H$8-Thresholds!$G$8))*0.18)))),3) -> 0.84 | P3: =ROUND(MIN(I3:O3),3) -> 0.548 | Q3: =IF(P3>=0.751,"Healthy",IF(P3>=0.501,"Moderate",IF(P3>=0.201,"Poor","Critical"))) -> Moderate | R3: =IF(P3>=0.5,1,0) -> 1 | S3: =IF(AND(F3>=10,F3<=35,P3>0.5),"ERROR_C3H3_POOR_CAP","OK") -> OK
A4: SYN-00003 | B4: 1118.54 | C4: 24.201 | D4: 29.346 | E4: 15.699 | F4: 0.255 | G4: 271.362 | H4: 367.749 | I4: =ROUND(IF(B4<=Thresholds!$B$2,1-(B4/Thresholds!$B$2)*0.24,IF(B4<=Thresholds!$D$2,0.75-((B4-Thresholds!$C$2)/(Thresholds!$D$2-Thresholds!$C$2))*0.249,IF(B4<=Thresholds!$F$2,0.499-((B4-Thresholds!$E$2)/(Thresholds!$F$2-Thresholds!$E$2))*0.279,MAX(0.02,0.2-((B4-Thresholds!$G$2)/(Thresholds!$H$2-Thresholds!$G$2))*0.18)))),3) -> 0.393 | J4: =ROUND(IF(C4<=Thresholds!$B$3,1-(C4/Thresholds!$B$3)*0.24,IF(C4<=Thresholds!$D$3,0.75-((C4-Thresholds!$C$3)/(Thresholds!$D$3-Thresholds!$C$3))*0.249,IF(C4<=Thresholds!$F$3,0.499-((C4-Thresholds!$E$3)/(Thresholds!$F$3-Thresholds!$E$3))*0.279,MAX(0.02,0.2-((C4-Thresholds!$G$3)/(Thresholds!$H$3-Thresholds!$G$3))*0.18)))),3) -> 0.952 | K4: =ROUND(IF(D4<=Thresholds!$B$4,1-(D4/Thresholds!$B$4)*0.24,IF(D4<=Thresholds!$D$4,0.75-((D4-Thresholds!$C$4)/(Thresholds!$D$4-Thresholds!$C$4))*0.249,IF(D4<=Thresholds!$F$4,0.499-((D4-Thresholds!$E$4)/(Thresholds!$F$4-Thresholds!$E$4))*0.279,MAX(0.02,0.2-((D4-Thresholds!$G$4)/(Thresholds!$H$4-Thresholds!$G$4))*0.18)))),3) -> 0.892 | L4: =ROUND(IF(E4<=Thresholds!$B$5,1-(E4/Thresholds!$B$5)*0.24,IF(E4<=Thresholds!$D$5,0.75-((E4-Thresholds!$C$5)/(Thresholds!$D$5-Thresholds!$C$5))*0.249,IF(E4<=Thresholds!$F$5,0.499-((E4-Thresholds!$E$5)/(Thresholds!$F$5-Thresholds!$E$5))*0.279,MAX(0.02,0.2-((E4-Thresholds!$G$5)/(Thresholds!$H$5-Thresholds!$G$5))*0.18)))),3) -> 0.925 | M4: =ROUND(IF(F4<=Thresholds!$B$6,1-(F4/Thresholds!$B$6)*0.24,IF(F4<=Thresholds!$D$6,0.75-((F4-Thresholds!$C$6)/(Thresholds!$D$6-Thresholds!$C$6))*0.249,IF(F4<=Thresholds!$F$6,0.499-((F4-Thresholds!$E$6)/(Thresholds!$F$6-Thresholds!$E$6))*0.279,MAX(0.02,0.2-((F4-Thresholds!$G$6)/(Thresholds!$H$6-Thresholds!$G$6))*0.18)))),3) -> 0.939 | N4: =ROUND(IF(G4<=Thresholds!$B$7,1-(G4/Thresholds!$B$7)*0.24,IF(G4<=Thresholds!$D$7,0.75-((G4-Thresholds!$C$7)/(Thresholds!$D$7-Thresholds!$C$7))*0.249,IF(G4<=Thresholds!$F$7,0.499-((G4-Thresholds!$E$7)/(Thresholds!$F$7-Thresholds!$E$7))*0.279,MAX(0.02,0.2-((G4-Thresholds!$G$7)/(Thresholds!$H$7-Thresholds!$G$7))*0.18)))),3) -> 0.814 | O4: =ROUND(IF(H4<=Thresholds!$B$8,1-(H4/Thresholds!$B$8)*0.24,IF(H4<=Thresholds!$D$8,0.75-((H4-Thresholds!$C$8)/(Thresholds!$D$8-Thresholds!$C$8))*0.249,IF(H4<=Thresholds!$F$8,0.499-((H4-Thresholds!$E$8)/(Thresholds!$F$8-Thresholds!$E$8))*0.279,MAX(0.02,0.2-((H4-Thresholds!$G$8)/(Thresholds!$H$8-Thresholds!$G$8))*0.18)))),3) -> 0.965 | P4: =ROUND(MIN(I4:O4),3) -> 0.393 | Q4: =IF(P4>=0.751,"Healthy",IF(P4>=0.501,"Moderate",IF(P4>=0.201,"Poor","Critical"))) -> Poor | R4: =IF(P4>=0.5,1,0) -> 0 | S4: =IF(AND(F4>=10,F4<=35,P4>0.5),"ERROR_C4H4_POOR_CAP","OK") -> OK
A5: SYN-00004 | B5: 62.354 | C5: 98.013 | D5: 274.581 | E5: 27.971 | F5: 0.974 | G5: 143.363 | H5: 1436.096 | I5: =ROUND(IF(B5<=Thresholds!$B$2,1-(B5/Thresholds!$B$2)*0.24,IF(B5<=Thresholds!$D$2,0.75-((B5-Thresholds!$C$2)/(Thresholds!$D$2-Thresholds!$C$2))*0.249,IF(B5<=Thresholds!$F$2,0.499-((B5-Thresholds!$E$2)/(Thresholds!$F$2-Thresholds!$E$2))*0.279,MAX(0.02,0.2-((B5-Thresholds!$G$2)/(Thresholds!$H$2-Thresholds!$G$2))*0.18)))),3) -> 0.85 | J5: =ROUND(IF(C5<=Thresholds!$B$3,1-(C5/Thresholds!$B$3)*0.24,IF(C5<=Thresholds!$D$3,0.75-((C5-Thresholds!$C$3)/(Thresholds!$D$3-Thresholds!$C$3))*0.249,IF(C5<=Thresholds!$F$3,0.499-((C5-Thresholds!$E$3)/(Thresholds!$F$3-Thresholds!$E$3))*0.279,MAX(0.02,0.2-((C5-Thresholds!$G$3)/(Thresholds!$H$3-Thresholds!$G$3))*0.18)))),3) -> 0.804 | K5: =ROUND(IF(D5<=Thresholds!$B$4,1-(D5/Thresholds!$B$4)*0.24,IF(D5<=Thresholds!$D$4,0.75-((D5-Thresholds!$C$4)/(Thresholds!$D$4-Thresholds!$C$4))*0.249,IF(D5<=Thresholds!$F$4,0.499-((D5-Thresholds!$E$4)/(Thresholds!$F$4-Thresholds!$E$4))*0.279,MAX(0.02,0.2-((D5-Thresholds!$G$4)/(Thresholds!$H$4-Thresholds!$G$4))*0.18)))),3) -> 0.347 | L5: =ROUND(IF(E5<=Thresholds!$B$5,1-(E5/Thresholds!$B$5)*0.24,IF(E5<=Thresholds!$D$5,0.75-((E5-Thresholds!$C$5)/(Thresholds!$D$5-Thresholds!$C$5))*0.249,IF(E5<=Thresholds!$F$5,0.499-((E5-Thresholds!$E$5)/(Thresholds!$F$5-Thresholds!$E$5))*0.279,MAX(0.02,0.2-((E5-Thresholds!$G$5)/(Thresholds!$H$5-Thresholds!$G$5))*0.18)))),3) -> 0.866 | M5: =ROUND(IF(F5<=Thresholds!$B$6,1-(F5/Thresholds!$B$6)*0.24,IF(F5<=Thresholds!$D$6,0.75-((F5-Thresholds!$C$6)/(Thresholds!$D$6-Thresholds!$C$6))*0.249,IF(F5<=Thresholds!$F$6,0.499-((F5-Thresholds!$E$6)/(Thresholds!$F$6-Thresholds!$E$6))*0.279,MAX(0.02,0.2-((F5-Thresholds!$G$6)/(Thresholds!$H$6-Thresholds!$G$6))*0.18)))),3) -> 0.766 | N5: =ROUND(IF(G5<=Thresholds!$B$7,1-(G5/Thresholds!$B$7)*0.24,IF(G5<=Thresholds!$D$7,0.75-((G5-Thresholds!$C$7)/(Thresholds!$D$7-Thresholds!$C$7))*0.249,IF(G5<=Thresholds!$F$7,0.499-((G5-Thresholds!$E$7)/(Thresholds!$F$7-Thresholds!$E$7))*0.279,MAX(0.02,0.2-((G5-Thresholds!$G$7)/(Thresholds!$H$7-Thresholds!$G$7))*0.18)))),3) -> 0.902 | O5: =ROUND(IF(H5<=Thresholds!$B$8,1-(H5/Thresholds!$B$8)*0.24,IF(H5<=Thresholds!$D$8,0.75-((H5-Thresholds!$C$8)/(Thresholds!$D$8-Thresholds!$C$8))*0.249,IF(H5<=Thresholds!$F$8,0.499-((H5-Thresholds!$E$8)/(Thresholds!$F$8-Thresholds!$E$8))*0.279,MAX(0.02,0.2-((H5-Thresholds!$G$8)/(Thresholds!$H$8-Thresholds!$G$8))*0.18)))),3) -> 0.862 | P5: =ROUND(MIN(I5:O5),3) -> 0.347 | Q5: =IF(P5>=0.751,"Healthy",IF(P5>=0.501,"Moderate",IF(P5>=0.201,"Poor","Critical"))) -> Poor | R5: =IF(P5>=0.5,1,0) -> 0 | S5: =IF(AND(F5>=10,F5<=35,P5>0.5),"ERROR_C5H5_POOR_CAP","OK") -> OK
A6: SYN-00005 | B6: 39.355 | C6: 27.921 | D6: 7.545 | E6: 33.91 | F6: 0.784 | G6: 345.086 | H6: 2156.38 | I6: =ROUND(IF(B6<=Thresholds!$B$2,1-(B6/Thresholds!$B$2)*0.24,IF(B6<=Thresholds!$D$2,0.75-((B6-Thresholds!$C$2)/(Thresholds!$D$2-Thresholds!$C$2))*0.249,IF(B6<=Thresholds!$F$2,0.499-((B6-Thresholds!$E$2)/(Thresholds!$F$2-Thresholds!$E$2))*0.279,MAX(0.02,0.2-((B6-Thresholds!$G$2)/(Thresholds!$H$2-Thresholds!$G$2))*0.18)))),3) -> 0.906 | J6: =ROUND(IF(C6<=Thresholds!$B$3,1-(C6/Thresholds!$B$3)*0.24,IF(C6<=Thresholds!$D$3,0.75-((C6-Thresholds!$C$3)/(Thresholds!$D$3-Thresholds!$C$3))*0.249,IF(C6<=Thresholds!$F$3,0.499-((C6-Thresholds!$E$3)/(Thresholds!$F$3-Thresholds!$E$3))*0.279,MAX(0.02,0.2-((C6-Thresholds!$G$3)/(Thresholds!$H$3-Thresholds!$G$3))*0.18)))),3) -> 0.944 | K6: =ROUND(IF(D6<=Thresholds!$B$4,1-(D6/Thresholds!$B$4)*0.24,IF(D6<=Thresholds!$D$4,0.75-((D6-Thresholds!$C$4)/(Thresholds!$D$4-Thresholds!$C$4))*0.249,IF(D6<=Thresholds!$F$4,0.499-((D6-Thresholds!$E$4)/(Thresholds!$F$4-Thresholds!$E$4))*0.279,MAX(0.02,0.2-((D6-Thresholds!$G$4)/(Thresholds!$H$4-Thresholds!$G$4))*0.18)))),3) -> 0.972 | L6: =ROUND(IF(E6<=Thresholds!$B$5,1-(E6/Thresholds!$B$5)*0.24,IF(E6<=Thresholds!$D$5,0.75-((E6-Thresholds!$C$5)/(Thresholds!$D$5-Thresholds!$C$5))*0.249,IF(E6<=Thresholds!$F$5,0.499-((E6-Thresholds!$E$5)/(Thresholds!$F$5-Thresholds!$E$5))*0.279,MAX(0.02,0.2-((E6-Thresholds!$G$5)/(Thresholds!$H$5-Thresholds!$G$5))*0.18)))),3) -> 0.837 | M6: =ROUND(IF(F6<=Thresholds!$B$6,1-(F6/Thresholds!$B$6)*0.24,IF(F6<=Thresholds!$D$6,0.75-((F6-Thresholds!$C$6)/(Thresholds!$D$6-Thresholds!$C$6))*0.249,IF(F6<=Thresholds!$F$6,0.499-((F6-Thresholds!$E$6)/(Thresholds!$F$6-Thresholds!$E$6))*0.279,MAX(0.02,0.2-((F6-Thresholds!$G$6)/(Thresholds!$H$6-Thresholds!$G$6))*0.18)))),3) -> 0.812 | N6: =ROUND(IF(G6<=Thresholds!$B$7,1-(G6/Thresholds!$B$7)*0.24,IF(G6<=Thresholds!$D$7,0.75-((G6-Thresholds!$C$7)/(Thresholds!$D$7-Thresholds!$C$7))*0.249,IF(G6<=Thresholds!$F$7,0.499-((G6-Thresholds!$E$7)/(Thresholds!$F$7-Thresholds!$E$7))*0.279,MAX(0.02,0.2-((G6-Thresholds!$G$7)/(Thresholds!$H$7-Thresholds!$G$7))*0.18)))),3) -> 0.763 | O6: =ROUND(IF(H6<=Thresholds!$B$8,1-(H6/Thresholds!$B$8)*0.24,IF(H6<=Thresholds!$D$8,0.75-((H6-Thresholds!$C$8)/(Thresholds!$D$8-Thresholds!$C$8))*0.249,IF(H6<=Thresholds!$F$8,0.499-((H6-Thresholds!$E$8)/(Thresholds!$F$8-Thresholds!$E$8))*0.279,MAX(0.02,0.2-((H6-Thresholds!$G$8)/(Thresholds!$H$8-Thresholds!$G$8))*0.18)))),3) -> 0.793 | P6: =ROUND(MIN(I6:O6),3) -> 0.763 | Q6: =IF(P6>=0.751,"Healthy",IF(P6>=0.501,"Moderate",IF(P6>=0.201,"Poor","Critical"))) -> Healthy | R6: =IF(P6>=0.5,1,0) -> 1 | S6: =IF(AND(F6>=10,F6<=35,P6>0.5),"ERROR_C6H6_POOR_CAP","OK") -> OK
A7: SYN-00006 | B7: 14.595 | C7: 37.689 | D7: 42.504 | E7: 19.83 | F7: 0.402 | G7: 87.161 | H7: 3905.045 | I7: =ROUND(IF(B7<=Thresholds!$B$2,1-(B7/Thresholds!$B$2)*0.24,IF(B7<=Thresholds!$D$2,0.75-((B7-Thresholds!$C$2)/(Thresholds!$D$2-Thresholds!$C$2))*0.249,IF(B7<=Thresholds!$F$2,0.499-((B7-Thresholds!$E$2)/(Thresholds!$F$2-Thresholds!$E$2))*0.279,MAX(0.02,0.2-((B7-Thresholds!$G$2)/(Thresholds!$H$2-Thresholds!$G$2))*0.18)))),3) -> 0.965 | J7: =ROUND(IF(C7<=Thresholds!$B$3,1-(C7/Thresholds!$B$3)*0.24,IF(C7<=Thresholds!$D$3,0.75-((C7-Thresholds!$C$3)/(Thresholds!$D$3-Thresholds!$C$3))*0.249,IF(C7<=Thresholds!$F$3,0.499-((C7-Thresholds!$E$3)/(Thresholds!$F$3-Thresholds!$E$3))*0.279,MAX(0.02,0.2-((C7-Thresholds!$G$3)/(Thresholds!$H$3-Thresholds!$G$3))*0.18)))),3) -> 0.925 | K7: =ROUND(IF(D7<=Thresholds!$B$4,1-(D7/Thresholds!$B$4)*0.24,IF(D7<=Thresholds!$D$4,0.75-((D7-Thresholds!$C$4)/(Thresholds!$D$4-Thresholds!$C$4))*0.249,IF(D7<=Thresholds!$F$4,0.499-((D7-Thresholds!$E$4)/(Thresholds!$F$4-Thresholds!$E$4))*0.279,MAX(0.02,0.2-((D7-Thresholds!$G$4)/(Thresholds!$H$4-Thresholds!$G$4))*0.18)))),3) -> 0.843 | L7: =ROUND(IF(E7<=Thresholds!$B$5,1-(E7/Thresholds!$B$5)*0.24,IF(E7<=Thresholds!$D$5,0.75-((E7-Thresholds!$C$5)/(Thresholds!$D$5-Thresholds!$C$5))*0.249,IF(E7<=Thresholds!$F$5,0.499-((E7-Thresholds!$E$5)/(Thresholds!$F$5-Thresholds!$E$5))*0.279,MAX(0.02,0.2-((E7-Thresholds!$G$5)/(Thresholds!$H$5-Thresholds!$G$5))*0.18)))),3) -> 0.905 | M7: =ROUND(IF(F7<=Thresholds!$B$6,1-(F7/Thresholds!$B$6)*0.24,IF(F7<=Thresholds!$D$6,0.75-((F7-Thresholds!$C$6)/(Thresholds!$D$6-Thresholds!$C$6))*0.249,IF(F7<=Thresholds!$F$6,0.499-((F7-Thresholds!$E$6)/(Thresholds!$F$6-Thresholds!$E$6))*0.279,MAX(0.02,0.2-((F7-Thresholds!$G$6)/(Thresholds!$H$6-Thresholds!$G$6))*0.18)))),3) -> 0.904 | N7: =ROUND(IF(G7<=Thresholds!$B$7,1-(G7/Thresholds!$B$7)*0.24,IF(G7<=Thresholds!$D$7,0.75-((G7-Thresholds!$C$7)/(Thresholds!$D$7-Thresholds!$C$7))*0.249,IF(G7<=Thresholds!$F$7,0.499-((G7-Thresholds!$E$7)/(Thresholds!$F$7-Thresholds!$E$7))*0.279,MAX(0.02,0.2-((G7-Thresholds!$G$7)/(Thresholds!$H$7-Thresholds!$G$7))*0.18)))),3) -> 0.94 | O7: =ROUND(IF(H7<=Thresholds!$B$8,1-(H7/Thresholds!$B$8)*0.24,IF(H7<=Thresholds!$D$8,0.75-((H7-Thresholds!$C$8)/(Thresholds!$D$8-Thresholds!$C$8))*0.249,IF(H7<=Thresholds!$F$8,0.499-((H7-Thresholds!$E$8)/(Thresholds!$F$8-Thresholds!$E$8))*0.279,MAX(0.02,0.2-((H7-Thresholds!$G$8)/(Thresholds!$H$8-Thresholds!$G$8))*0.18)))),3) -> 0.517 | P7: =ROUND(MIN(I7:O7),3) -> 0.517 | Q7: =IF(P7>=0.751,"Healthy",IF(P7>=0.501,"Moderate",IF(P7>=0.201,"Poor","Critical"))) -> Moderate | R7: =IF(P7>=0.5,1,0) -> 1 | S7: =IF(AND(F7>=10,F7<=35,P7>0.5),"ERROR_C7H7_POOR_CAP","OK") -> OK
A8: SYN-00007 | B8: 593.26 | C8: 66.892 | D8: 18.367 | E8: 24.457 | F8: 15.49 | G8: 325.193 | H8: 1759.385 | I8: =ROUND(IF(B8<=Thresholds!$B$2,1-(B8/Thresholds!$B$2)*0.24,IF(B8<=Thresholds!$D$2,0.75-((B8-Thresholds!$C$2)/(Thresholds!$D$2-Thresholds!$C$2))*0.249,IF(B8<=Thresholds!$F$2,0.499-((B8-Thresholds!$E$2)/(Thresholds!$F$2-Thresholds!$E$2))*0.279,MAX(0.02,0.2-((B8-Thresholds!$G$2)/(Thresholds!$H$2-Thresholds!$G$2))*0.18)))),3) -> 0.545 | J8: =ROUND(IF(C8<=Thresholds!$B$3,1-(C8/Thresholds!$B$3)*0.24,IF(C8<=Thresholds!$D$3,0.75-((C8-Thresholds!$C$3)/(Thresholds!$D$3-Thresholds!$C$3))*0.249,IF(C8<=Thresholds!$F$3,0.499-((C8-Thresholds!$E$3)/(Thresholds!$F$3-Thresholds!$E$3))*0.279,MAX(0.02,0.2-((C8-Thresholds!$G$3)/(Thresholds!$H$3-Thresholds!$G$3))*0.18)))),3) -> 0.866 | K8: =ROUND(IF(D8<=Thresholds!$B$4,1-(D8/Thresholds!$B$4)*0.24,IF(D8<=Thresholds!$D$4,0.75-((D8-Thresholds!$C$4)/(Thresholds!$D$4-Thresholds!$C$4))*0.249,IF(D8<=Thresholds!$F$4,0.499-((D8-Thresholds!$E$4)/(Thresholds!$F$4-Thresholds!$E$4))*0.279,MAX(0.02,0.2-((D8-Thresholds!$G$4)/(Thresholds!$H$4-Thresholds!$G$4))*0.18)))),3) -> 0.932 | L8: =ROUND(IF(E8<=Thresholds!$B$5,1-(E8/Thresholds!$B$5)*0.24,IF(E8<=Thresholds!$D$5,0.75-((E8-Thresholds!$C$5)/(Thresholds!$D$5-Thresholds!$C$5))*0.249,IF(E8<=Thresholds!$F$5,0.499-((E8-Thresholds!$E$5)/(Thresholds!$F$5-Thresholds!$E$5))*0.279,MAX(0.02,0.2-((E8-Thresholds!$G$5)/(Thresholds!$H$5-Thresholds!$G$5))*0.18)))),3) -> 0.883 | M8: =ROUND(IF(F8<=Thresholds!$B$6,1-(F8/Thresholds!$B$6)*0.24,IF(F8<=Thresholds!$D$6,0.75-((F8-Thresholds!$C$6)/(Thresholds!$D$6-Thresholds!$C$6))*0.249,IF(F8<=Thresholds!$F$6,0.499-((F8-Thresholds!$E$6)/(Thresholds!$F$6-Thresholds!$E$6))*0.279,MAX(0.02,0.2-((F8-Thresholds!$G$6)/(Thresholds!$H$6-Thresholds!$G$6))*0.18)))),3) -> 0.438 | N8: =ROUND(IF(G8<=Thresholds!$B$7,1-(G8/Thresholds!$B$7)*0.24,IF(G8<=Thresholds!$D$7,0.75-((G8-Thresholds!$C$7)/(Thresholds!$D$7-Thresholds!$C$7))*0.249,IF(G8<=Thresholds!$F$7,0.499-((G8-Thresholds!$E$7)/(Thresholds!$F$7-Thresholds!$E$7))*0.279,MAX(0.02,0.2-((G8-Thresholds!$G$7)/(Thresholds!$H$7-Thresholds!$G$7))*0.18)))),3) -> 0.777 | O8: =ROUND(IF(H8<=Thresholds!$B$8,1-(H8/Thresholds!$B$8)*0.24,IF(H8<=Thresholds!$D$8,0.75-((H8-Thresholds!$C$8)/(Thresholds!$D$8-Thresholds!$C$8))*0.249,IF(H8<=Thresholds!$F$8,0.499-((H8-Thresholds!$E$8)/(Thresholds!$F$8-Thresholds!$E$8))*0.279,MAX(0.02,0.2-((H8-Thresholds!$G$8)/(Thresholds!$H$8-Thresholds!$G$8))*0.18)))),3) -> 0.831 | P8: =ROUND(MIN(I8:O8),3) -> 0.438 | Q8: =IF(P8>=0.751,"Healthy",IF(P8>=0.501,"Moderate",IF(P8>=0.201,"Poor","Critical"))) -> Poor | R8: =IF(P8>=0.5,1,0) -> 0 | S8: =IF(AND(F8>=10,F8<=35,P8>0.5),"ERROR_C8H8_POOR_CAP","OK") -> OK
A9: SYN-00008 | B9: 34.968 | C9: 36.522 | D9: 16.278 | E9: 47.288 | F9: 0.883 | G9: 122.13 | H9: 13956.923 | I9: =ROUND(IF(B9<=Thresholds!$B$2,1-(B9/Thresholds!$B$2)*0.24,IF(B9<=Thresholds!$D$2,0.75-((B9-Thresholds!$C$2)/(Thresholds!$D$2-Thresholds!$C$2))*0.249,IF(B9<=Thresholds!$F$2,0.499-((B9-Thresholds!$E$2)/(Thresholds!$F$2-Thresholds!$E$2))*0.279,MAX(0.02,0.2-((B9-Thresholds!$G$2)/(Thresholds!$H$2-Thresholds!$G$2))*0.18)))),3) -> 0.916 | J9: =ROUND(IF(C9<=Thresholds!$B$3,1-(C9/Thresholds!$B$3)*0.24,IF(C9<=Thresholds!$D$3,0.75-((C9-Thresholds!$C$3)/(Thresholds!$D$3-Thresholds!$C$3))*0.249,IF(C9<=Thresholds!$F$3,0.499-((C9-Thresholds!$E$3)/(Thresholds!$F$3-Thresholds!$E$3))*0.279,MAX(0.02,0.2-((C9-Thresholds!$G$3)/(Thresholds!$H$3-Thresholds!$G$3))*0.18)))),3) -> 0.927 | K9: =ROUND(IF(D9<=Thresholds!$B$4,1-(D9/Thresholds!$B$4)*0.24,IF(D9<=Thresholds!$D$4,0.75-((D9-Thresholds!$C$4)/(Thresholds!$D$4-Thresholds!$C$4))*0.249,IF(D9<=Thresholds!$F$4,0.499-((D9-Thresholds!$E$4)/(Thresholds!$F$4-Thresholds!$E$4))*0.279,MAX(0.02,0.2-((D9-Thresholds!$G$4)/(Thresholds!$H$4-Thresholds!$G$4))*0.18)))),3) -> 0.94 | L9: =ROUND(IF(E9<=Thresholds!$B$5,1-(E9/Thresholds!$B$5)*0.24,IF(E9<=Thresholds!$D$5,0.75-((E9-Thresholds!$C$5)/(Thresholds!$D$5-Thresholds!$C$5))*0.249,IF(E9<=Thresholds!$F$5,0.499-((E9-Thresholds!$E$5)/(Thresholds!$F$5-Thresholds!$E$5))*0.279,MAX(0.02,0.2-((E9-Thresholds!$G$5)/(Thresholds!$H$5-Thresholds!$G$5))*0.18)))),3) -> 0.773 | M9: =ROUND(IF(F9<=Thresholds!$B$6,1-(F9/Thresholds!$B$6)*0.24,IF(F9<=Thresholds!$D$6,0.75-((F9-Thresholds!$C$6)/(Thresholds!$D$6-Thresholds!$C$6))*0.249,IF(F9<=Thresholds!$F$6,0.499-((F9-Thresholds!$E$6)/(Thresholds!$F$6-Thresholds!$E$6))*0.279,MAX(0.02,0.2-((F9-Thresholds!$G$6)/(Thresholds!$H$6-Thresholds!$G$6))*0.18)))),3) -> 0.788 | N9: =ROUND(IF(G9<=Thresholds!$B$7,1-(G9/Thresholds!$B$7)*0.24,IF(G9<=Thresholds!$D$7,0.75-((G9-Thresholds!$C$7)/(Thresholds!$D$7-Thresholds!$C$7))*0.249,IF(G9<=Thresholds!$F$7,0.499-((G9-Thresholds!$E$7)/(Thresholds!$F$7-Thresholds!$E$7))*0.279,MAX(0.02,0.2-((G9-Thresholds!$G$7)/(Thresholds!$H$7-Thresholds!$G$7))*0.18)))),3) -> 0.916 | O9: =ROUND(IF(H9<=Thresholds!$B$8,1-(H9/Thresholds!$B$8)*0.24,IF(H9<=Thresholds!$D$8,0.75-((H9-Thresholds!$C$8)/(Thresholds!$D$8-Thresholds!$C$8))*0.249,IF(H9<=Thresholds!$F$8,0.499-((H9-Thresholds!$E$8)/(Thresholds!$F$8-Thresholds!$E$8))*0.279,MAX(0.02,0.2-((H9-Thresholds!$G$8)/(Thresholds!$H$8-Thresholds!$G$8))*0.18)))),3) -> 0.271 | P9: =ROUND(MIN(I9:O9),3) -> 0.271 | Q9: =IF(P9>=0.751,"Healthy",IF(P9>=0.501,"Moderate",IF(P9>=0.201,"Poor","Critical"))) -> Poor | R9: =IF(P9>=0.5,1,0) -> 0 | S9: =IF(AND(F9>=10,F9<=35,P9>0.5),"ERROR_C9H9_POOR_CAP","OK") -> OK
A10: SYN-00009 | B10: 18.573 | C10: 21.918 | D10: 49.253 | E10: 28.101 | F10: 0.76 | G10: 159.954 | H10: 1510.891 | I10: =ROUND(IF(B10<=Thresholds!$B$2,1-(B10/Thresholds!$B$2)*0.24,IF(B10<=Thresholds!$D$2,0.75-((B10-Thresholds!$C$2)/(Thresholds!$D$2-Thresholds!$C$2))*0.249,IF(B10<=Thresholds!$F$2,0.499-((B10-Thresholds!$E$2)/(Thresholds!$F$2-Thresholds!$E$2))*0.279,MAX(0.02,0.2-((B10-Thresholds!$G$2)/(Thresholds!$H$2-Thresholds!$G$2))*0.18)))),3) -> 0.955 | J10: =ROUND(IF(C10<=Thresholds!$B$3,1-(C10/Thresholds!$B$3)*0.24,IF(C10<=Thresholds!$D$3,0.75-((C10-Thresholds!$C$3)/(Thresholds!$D$3-Thresholds!$C$3))*0.249,IF(C10<=Thresholds!$F$3,0.499-((C10-Thresholds!$E$3)/(Thresholds!$F$3-Thresholds!$E$3))*0.279,MAX(0.02,0.2-((C10-Thresholds!$G$3)/(Thresholds!$H$3-Thresholds!$G$3))*0.18)))),3) -> 0.956 | K10: =ROUND(IF(D10<=Thresholds!$B$4,1-(D10/Thresholds!$B$4)*0.24,IF(D10<=Thresholds!$D$4,0.75-((D10-Thresholds!$C$4)/(Thresholds!$D$4-Thresholds!$C$4))*0.249,IF(D10<=Thresholds!$F$4,0.499-((D10-Thresholds!$E$4)/(Thresholds!$F$4-Thresholds!$E$4))*0.279,MAX(0.02,0.2-((D10-Thresholds!$G$4)/(Thresholds!$H$4-Thresholds!$G$4))*0.18)))),3) -> 0.818 | L10: =ROUND(IF(E10<=Thresholds!$B$5,1-(E10/Thresholds!$B$5)*0.24,IF(E10<=Thresholds!$D$5,0.75-((E10-Thresholds!$C$5)/(Thresholds!$D$5-Thresholds!$C$5))*0.249,IF(E10<=Thresholds!$F$5,0.499-((E10-Thresholds!$E$5)/(Thresholds!$F$5-Thresholds!$E$5))*0.279,MAX(0.02,0.2-((E10-Thresholds!$G$5)/(Thresholds!$H$5-Thresholds!$G$5))*0.18)))),3) -> 0.865 | M10: =ROUND(IF(F10<=Thresholds!$B$6,1-(F10/Thresholds!$B$6)*0.24,IF(F10<=Thresholds!$D$6,0.75-((F10-Thresholds!$C$6)/(Thresholds!$D$6-Thresholds!$C$6))*0.249,IF(F10<=Thresholds!$F$6,0.499-((F10-Thresholds!$E$6)/(Thresholds!$F$6-Thresholds!$E$6))*0.279,MAX(0.02,0.2-((F10-Thresholds!$G$6)/(Thresholds!$H$6-Thresholds!$G$6))*0.18)))),3) -> 0.818 | N10: =ROUND(IF(G10<=Thresholds!$B$7,1-(G10/Thresholds!$B$7)*0.24,IF(G10<=Thresholds!$D$7,0.75-((G10-Thresholds!$C$7)/(Thresholds!$D$7-Thresholds!$C$7))*0.249,IF(G10<=Thresholds!$F$7,0.499-((G10-Thresholds!$E$7)/(Thresholds!$F$7-Thresholds!$E$7))*0.279,MAX(0.02,0.2-((G10-Thresholds!$G$7)/(Thresholds!$H$7-Thresholds!$G$7))*0.18)))),3) -> 0.89 | O10: =ROUND(IF(H10<=Thresholds!$B$8,1-(H10/Thresholds!$B$8)*0.24,IF(H10<=Thresholds!$D$8,0.75-((H10-Thresholds!$C$8)/(Thresholds!$D$8-Thresholds!$C$8))*0.249,IF(H10<=Thresholds!$F$8,0.499-((H10-Thresholds!$E$8)/(Thresholds!$F$8-Thresholds!$E$8))*0.279,MAX(0.02,0.2-((H10-Thresholds!$G$8)/(Thresholds!$H$8-Thresholds!$G$8))*0.18)))),3) -> 0.855 | P10: =ROUND(MIN(I10:O10),3) -> 0.818 | Q10: =IF(P10>=0.751,"Healthy",IF(P10>=0.501,"Moderate",IF(P10>=0.201,"Poor","Critical"))) -> Healthy | R10: =IF(P10>=0.5,1,0) -> 1 | S10: =IF(AND(F10>=10,F10<=35,P10>0.5),"ERROR_C10H10_POOR_CAP","OK") -> OK
A11: SYN-00010 | B11: 25.835 | C11: 119.719 | D11: 92.931 | E11: 6.818 | F11: 0.095 | G11: 53.958 | H11: 1615.184 | I11: =ROUND(IF(B11<=Thresholds!$B$2,1-(B11/Thresholds!$B$2)*0.24,IF(B11<=Thresholds!$D$2,0.75-((B11-Thresholds!$C$2)/(Thresholds!$D$2-Thresholds!$C$2))*0.249,IF(B11<=Thresholds!$F$2,0.499-((B11-Thresholds!$E$2)/(Thresholds!$F$2-Thresholds!$E$2))*0.279,MAX(0.02,0.2-((B11-Thresholds!$G$2)/(Thresholds!$H$2-Thresholds!$G$2))*0.18)))),3) -> 0.938 | J11: =ROUND(IF(C11<=Thresholds!$B$3,1-(C11/Thresholds!$B$3)*0.24,IF(C11<=Thresholds!$D$3,0.75-((C11-Thresholds!$C$3)/(Thresholds!$D$3-Thresholds!$C$3))*0.249,IF(C11<=Thresholds!$F$3,0.499-((C11-Thresholds!$E$3)/(Thresholds!$F$3-Thresholds!$E$3))*0.279,MAX(0.02,0.2-((C11-Thresholds!$G$3)/(Thresholds!$H$3-Thresholds!$G$3))*0.18)))),3) -> 0.761 | K11: =ROUND(IF(D11<=Thresholds!$B$4,1-(D11/Thresholds!$B$4)*0.24,IF(D11<=Thresholds!$D$4,0.75-((D11-Thresholds!$C$4)/(Thresholds!$D$4-Thresholds!$C$4))*0.249,IF(D11<=Thresholds!$F$4,0.499-((D11-Thresholds!$E$4)/(Thresholds!$F$4-Thresholds!$E$4))*0.279,MAX(0.02,0.2-((D11-Thresholds!$G$4)/(Thresholds!$H$4-Thresholds!$G$4))*0.18)))),3) -> 0.553 | L11: =ROUND(IF(E11<=Thresholds!$B$5,1-(E11/Thresholds!$B$5)*0.24,IF(E11<=Thresholds!$D$5,0.75-((E11-Thresholds!$C$5)/(Thresholds!$D$5-Thresholds!$C$5))*0.249,IF(E11<=Thresholds!$F$5,0.499-((E11-Thresholds!$E$5)/(Thresholds!$F$5-Thresholds!$E$5))*0.279,MAX(0.02,0.2-((E11-Thresholds!$G$5)/(Thresholds!$H$5-Thresholds!$G$5))*0.18)))),3) -> 0.967 | M11: =ROUND(IF(F11<=Thresholds!$B$6,1-(F11/Thresholds!$B$6)*0.24,IF(F11<=Thresholds!$D$6,0.75-((F11-Thresholds!$C$6)/(Thresholds!$D$6-Thresholds!$C$6))*0.249,IF(F11<=Thresholds!$F$6,0.499-((F11-Thresholds!$E$6)/(Thresholds!$F$6-Thresholds!$E$6))*0.279,MAX(0.02,0.2-((F11-Thresholds!$G$6)/(Thresholds!$H$6-Thresholds!$G$6))*0.18)))),3) -> 0.977 | N11: =ROUND(IF(G11<=Thresholds!$B$7,1-(G11/Thresholds!$B$7)*0.24,IF(G11<=Thresholds!$D$7,0.75-((G11-Thresholds!$C$7)/(Thresholds!$D$7-Thresholds!$C$7))*0.249,IF(G11<=Thresholds!$F$7,0.499-((G11-Thresholds!$E$7)/(Thresholds!$F$7-Thresholds!$E$7))*0.279,MAX(0.02,0.2-((G11-Thresholds!$G$7)/(Thresholds!$H$7-Thresholds!$G$7))*0.18)))),3) -> 0.963 | O11: =ROUND(IF(H11<=Thresholds!$B$8,1-(H11/Thresholds!$B$8)*0.24,IF(H11<=Thresholds!$D$8,0.75-((H11-Thresholds!$C$8)/(Thresholds!$D$8-Thresholds!$C$8))*0.249,IF(H11<=Thresholds!$F$8,0.499-((H11-Thresholds!$E$8)/(Thresholds!$F$8-Thresholds!$E$8))*0.279,MAX(0.02,0.2-((H11-Thresholds!$G$8)/(Thresholds!$H$8-Thresholds!$G$8))*0.18)))),3) -> 0.845 | P11: =ROUND(MIN(I11:O11),3) -> 0.553 | Q11: =IF(P11>=0.751,"Healthy",IF(P11>=0.501,"Moderate",IF(P11>=0.201,"Poor","Critical"))) -> Moderate | R11: =IF(P11>=0.5,1,0) -> 1 | S11: =IF(AND(F11>=10,F11<=35,P11>0.5),"ERROR_C11H11_POOR_CAP","OK") -> OK
A12: SYN-00011 | B12: 826.892 | C12: 73.931 | D12: 32.152 | E12: 14.442 | F12: 0.576 | G12: 330.858 | H12: 1740.673 | I12: =ROUND(IF(B12<=Thresholds!$B$2,1-(B12/Thresholds!$B$2)*0.24,IF(B12<=Thresholds!$D$2,0.75-((B12-Thresholds!$C$2)/(Thresholds!$D$2-Thresholds!$C$2))*0.249,IF(B12<=Thresholds!$F$2,0.499-((B12-Thresholds!$E$2)/(Thresholds!$F$2-Thresholds!$E$2))*0.279,MAX(0.02,0.2-((B12-Thresholds!$G$2)/(Thresholds!$H$2-Thresholds!$G$2))*0.18)))),3) -> 0.467 | J12: =ROUND(IF(C12<=Thresholds!$B$3,1-(C12/Thresholds!$B$3)*0.24,IF(C12<=Thresholds!$D$3,0.75-((C12-Thresholds!$C$3)/(Thresholds!$D$3-Thresholds!$C$3))*0.249,IF(C12<=Thresholds!$F$3,0.499-((C12-Thresholds!$E$3)/(Thresholds!$F$3-Thresholds!$E$3))*0.279,MAX(0.02,0.2-((C12-Thresholds!$G$3)/(Thresholds!$H$3-Thresholds!$G$3))*0.18)))),3) -> 0.852 | K12: =ROUND(IF(D12<=Thresholds!$B$4,1-(D12/Thresholds!$B$4)*0.24,IF(D12<=Thresholds!$D$4,0.75-((D12-Thresholds!$C$4)/(Thresholds!$D$4-Thresholds!$C$4))*0.249,IF(D12<=Thresholds!$F$4,0.499-((D12-Thresholds!$E$4)/(Thresholds!$F$4-Thresholds!$E$4))*0.279,MAX(0.02,0.2-((D12-Thresholds!$G$4)/(Thresholds!$H$4-Thresholds!$G$4))*0.18)))),3) -> 0.881 | L12: =ROUND(IF(E12<=Thresholds!$B$5,1-(E12/Thresholds!$B$5)*0.24,IF(E12<=Thresholds!$D$5,0.75-((E12-Thresholds!$C$5)/(Thresholds!$D$5-Thresholds!$C$5))*0.249,IF(E12<=Thresholds!$F$5,0.499-((E12-Thresholds!$E$5)/(Thresholds!$F$5-Thresholds!$E$5))*0.279,MAX(0.02,0.2-((E12-Thresholds!$G$5)/(Thresholds!$H$5-Thresholds!$G$5))*0.18)))),3) -> 0.931 | M12: =ROUND(IF(F12<=Thresholds!$B$6,1-(F12/Thresholds!$B$6)*0.24,IF(F12<=Thresholds!$D$6,0.75-((F12-Thresholds!$C$6)/(Thresholds!$D$6-Thresholds!$C$6))*0.249,IF(F12<=Thresholds!$F$6,0.499-((F12-Thresholds!$E$6)/(Thresholds!$F$6-Thresholds!$E$6))*0.279,MAX(0.02,0.2-((F12-Thresholds!$G$6)/(Thresholds!$H$6-Thresholds!$G$6))*0.18)))),3) -> 0.862 | N12: =ROUND(IF(G12<=Thresholds!$B$7,1-(G12/Thresholds!$B$7)*0.24,IF(G12<=Thresholds!$D$7,0.75-((G12-Thresholds!$C$7)/(Thresholds!$D$7-Thresholds!$C$7))*0.249,IF(G12<=Thresholds!$F$7,0.499-((G12-Thresholds!$E$7)/(Thresholds!$F$7-Thresholds!$E$7))*0.279,MAX(0.02,0.2-((G12-Thresholds!$G$7)/(Thresholds!$H$7-Thresholds!$G$7))*0.18)))),3) -> 0.773 | O12: =ROUND(IF(H12<=Thresholds!$B$8,1-(H12/Thresholds!$B$8)*0.24,IF(H12<=Thresholds!$D$8,0.75-((H12-Thresholds!$C$8)/(Thresholds!$D$8-Thresholds!$C$8))*0.249,IF(H12<=Thresholds!$F$8,0.499-((H12-Thresholds!$E$8)/(Thresholds!$F$8-Thresholds!$E$8))*0.279,MAX(0.02,0.2-((H12-Thresholds!$G$8)/(Thresholds!$H$8-Thresholds!$G$8))*0.18)))),3) -> 0.833 | P12: =ROUND(MIN(I12:O12),3) -> 0.467 | Q12: =IF(P12>=0.751,"Healthy",IF(P12>=0.501,"Moderate",IF(P12>=0.201,"Poor","Critical"))) -> Poor | R12: =IF(P12>=0.5,1,0) -> 0 | S12: =IF(AND(F12>=10,F12<=35,P12>0.5),"ERROR_C12H12_POOR_CAP","OK") -> OK
A13: SYN-00012 | B13: 30.348 | C13: 79.07 | D13: 10.138 | E13: 23.151 | F13: 0.481 | G13: 334.644 | H13: 12634.627 | I13: =ROUND(IF(B13<=Thresholds!$B$2,1-(B13/Thresholds!$B$2)*0.24,IF(B13<=Thresholds!$D$2,0.75-((B13-Thresholds!$C$2)/(Thresholds!$D$2-Thresholds!$C$2))*0.249,IF(B13<=Thresholds!$F$2,0.499-((B13-Thresholds!$E$2)/(Thresholds!$F$2-Thresholds!$E$2))*0.279,MAX(0.02,0.2-((B13-Thresholds!$G$2)/(Thresholds!$H$2-Thresholds!$G$2))*0.18)))),3) -> 0.927 | J13: =ROUND(IF(C13<=Thresholds!$B$3,1-(C13/Thresholds!$B$3)*0.24,IF(C13<=Thresholds!$D$3,0.75-((C13-Thresholds!$C$3)/(Thresholds!$D$3-Thresholds!$C$3))*0.249,IF(C13<=Thresholds!$F$3,0.499-((C13-Thresholds!$E$3)/(Thresholds!$F$3-Thresholds!$E$3))*0.279,MAX(0.02,0.2-((C13-Thresholds!$G$3)/(Thresholds!$H$3-Thresholds!$G$3))*0.18)))),3) -> 0.842 | K13: =ROUND(IF(D13<=Thresholds!$B$4,1-(D13/Thresholds!$B$4)*0.24,IF(D13<=Thresholds!$D$4,0.75-((D13-Thresholds!$C$4)/(Thresholds!$D$4-Thresholds!$C$4))*0.249,IF(D13<=Thresholds!$F$4,0.499-((D13-Thresholds!$E$4)/(Thresholds!$F$4-Thresholds!$E$4))*0.279,MAX(0.02,0.2-((D13-Thresholds!$G$4)/(Thresholds!$H$4-Thresholds!$G$4))*0.18)))),3) -> 0.963 | L13: =ROUND(IF(E13<=Thresholds!$B$5,1-(E13/Thresholds!$B$5)*0.24,IF(E13<=Thresholds!$D$5,0.75-((E13-Thresholds!$C$5)/(Thresholds!$D$5-Thresholds!$C$5))*0.249,IF(E13<=Thresholds!$F$5,0.499-((E13-Thresholds!$E$5)/(Thresholds!$F$5-Thresholds!$E$5))*0.279,MAX(0.02,0.2-((E13-Thresholds!$G$5)/(Thresholds!$H$5-Thresholds!$G$5))*0.18)))),3) -> 0.889 | M13: =ROUND(IF(F13<=Thresholds!$B$6,1-(F13/Thresholds!$B$6)*0.24,IF(F13<=Thresholds!$D$6,0.75-((F13-Thresholds!$C$6)/(Thresholds!$D$6-Thresholds!$C$6))*0.249,IF(F13<=Thresholds!$F$6,0.499-((F13-Thresholds!$E$6)/(Thresholds!$F$6-Thresholds!$E$6))*0.279,MAX(0.02,0.2-((F13-Thresholds!$G$6)/(Thresholds!$H$6-Thresholds!$G$6))*0.18)))),3) -> 0.885 | N13: =ROUND(IF(G13<=Thresholds!$B$7,1-(G13/Thresholds!$B$7)*0.24,IF(G13<=Thresholds!$D$7,0.75-((G13-Thresholds!$C$7)/(Thresholds!$D$7-Thresholds!$C$7))*0.249,IF(G13<=Thresholds!$F$7,0.499-((G13-Thresholds!$E$7)/(Thresholds!$F$7-Thresholds!$E$7))*0.279,MAX(0.02,0.2-((G13-Thresholds!$G$7)/(Thresholds!$H$7-Thresholds!$G$7))*0.18)))),3) -> 0.771 | O13: =ROUND(IF(H13<=Thresholds!$B$8,1-(H13/Thresholds!$B$8)*0.24,IF(H13<=Thresholds!$D$8,0.75-((H13-Thresholds!$C$8)/(Thresholds!$D$8-Thresholds!$C$8))*0.249,IF(H13<=Thresholds!$F$8,0.499-((H13-Thresholds!$E$8)/(Thresholds!$F$8-Thresholds!$E$8))*0.279,MAX(0.02,0.2-((H13-Thresholds!$G$8)/(Thresholds!$H$8-Thresholds!$G$8))*0.18)))),3) -> 0.247 | P13: =ROUND(MIN(I13:O13),3) -> 0.247 | Q13: =IF(P13>=0.751,"Healthy",IF(P13>=0.501,"Moderate",IF(P13>=0.201,"Poor","Critical"))) -> Poor | R13: =IF(P13>=0.5,1,0) -> 0 | S13: =IF(AND(F13>=10,F13<=35,P13>0.5),"ERROR_C13H13_POOR_CAP","OK") -> OK
A14: SYN-00013 | B14: 53.23 | C14: 18.131 | D14: 41.862 | E14: 42.479 | F14: 0.532 | G14: 83.638 | H14: 1013.045 | I14: =ROUND(IF(B14<=Thresholds!$B$2,1-(B14/Thresholds!$B$2)*0.24,IF(B14<=Thresholds!$D$2,0.75-((B14-Thresholds!$C$2)/(Thresholds!$D$2-Thresholds!$C$2))*0.249,IF(B14<=Thresholds!$F$2,0.499-((B14-Thresholds!$E$2)/(Thresholds!$F$2-Thresholds!$E$2))*0.279,MAX(0.02,0.2-((B14-Thresholds!$G$2)/(Thresholds!$H$2-Thresholds!$G$2))*0.18)))),3) -> 0.872 | J14: =ROUND(IF(C14<=Thresholds!$B$3,1-(C14/Thresholds!$B$3)*0.24,IF(C14<=Thresholds!$D$3,0.75-((C14-Thresholds!$C$3)/(Thresholds!$D$3-Thresholds!$C$3))*0.249,IF(C14<=Thresholds!$F$3,0.499-((C14-Thresholds!$E$3)/(Thresholds!$F$3-Thresholds!$E$3))*0.279,MAX(0.02,0.2-((C14-Thresholds!$G$3)/(Thresholds!$H$3-Thresholds!$G$3))*0.18)))),3) -> 0.964 | K14: =ROUND(IF(D14<=Thresholds!$B$4,1-(D14/Thresholds!$B$4)*0.24,IF(D14<=Thresholds!$D$4,0.75-((D14-Thresholds!$C$4)/(Thresholds!$D$4-Thresholds!$C$4))*0.249,IF(D14<=Thresholds!$F$4,0.499-((D14-Thresholds!$E$4)/(Thresholds!$F$4-Thresholds!$E$4))*0.279,MAX(0.02,0.2-((D14-Thresholds!$G$4)/(Thresholds!$H$4-Thresholds!$G$4))*0.18)))),3) -> 0.845 | L14: =ROUND(IF(E14<=Thresholds!$B$5,1-(E14/Thresholds!$B$5)*0.24,IF(E14<=Thresholds!$D$5,0.75-((E14-Thresholds!$C$5)/(Thresholds!$D$5-Thresholds!$C$5))*0.249,IF(E14<=Thresholds!$F$5,0.499-((E14-Thresholds!$E$5)/(Thresholds!$F$5-Thresholds!$E$5))*0.279,MAX(0.02,0.2-((E14-Thresholds!$G$5)/(Thresholds!$H$5-Thresholds!$G$5))*0.18)))),3) -> 0.796 | M14: =ROUND(IF(F14<=Thresholds!$B$6,1-(F14/Thresholds!$B$6)*0.24,IF(F14<=Thresholds!$D$6,0.75-((F14-Thresholds!$C$6)/(Thresholds!$D$6-Thresholds!$C$6))*0.249,IF(F14<=Thresholds!$F$6,0.499-((F14-Thresholds!$E$6)/(Thresholds!$F$6-Thresholds!$E$6))*0.279,MAX(0.02,0.2-((F14-Thresholds!$G$6)/(Thresholds!$H$6-Thresholds!$G$6))*0.18)))),3) -> 0.872 | N14: =ROUND(IF(G14<=Thresholds!$B$7,1-(G14/Thresholds!$B$7)*0.24,IF(G14<=Thresholds!$D$7,0.75-((G14-Thresholds!$C$7)/(Thresholds!$D$7-Thresholds!$C$7))*0.249,IF(G14<=Thresholds!$F$7,0.499-((G14-Thresholds!$E$7)/(Thresholds!$F$7-Thresholds!$E$7))*0.279,MAX(0.02,0.2-((G14-Thresholds!$G$7)/(Thresholds!$H$7-Thresholds!$G$7))*0.18)))),3) -> 0.943 | O14: =ROUND(IF(H14<=Thresholds!$B$8,1-(H14/Thresholds!$B$8)*0.24,IF(H14<=Thresholds!$D$8,0.75-((H14-Thresholds!$C$8)/(Thresholds!$D$8-Thresholds!$C$8))*0.249,IF(H14<=Thresholds!$F$8,0.499-((H14-Thresholds!$E$8)/(Thresholds!$F$8-Thresholds!$E$8))*0.279,MAX(0.02,0.2-((H14-Thresholds!$G$8)/(Thresholds!$H$8-Thresholds!$G$8))*0.18)))),3) -> 0.903 | P14: =ROUND(MIN(I14:O14),3) -> 0.796 | Q14: =IF(P14>=0.751,"Healthy",IF(P14>=0.501,"Moderate",IF(P14>=0.201,"Poor","Critical"))) -> Healthy | R14: =IF(P14>=0.5,1,0) -> 1 | S14: =IF(AND(F14>=10,F14<=35,P14>0.5),"ERROR_C14H14_POOR_CAP","OK") -> OK
A15: SYN-00014 | B15: 56.241 | C15: 366.163 | D15: 35.999 | E15: 2.527 | F15: 0.358 | G15: 23.976 | H15: 2331.609 | I15: =ROUND(IF(B15<=Thresholds!$B$2,1-(B15/Thresholds!$B$2)*0.24,IF(B15<=Thresholds!$D$2,0.75-((B15-Thresholds!$C$2)/(Thresholds!$D$2-Thresholds!$C$2))*0.249,IF(B15<=Thresholds!$F$2,0.499-((B15-Thresholds!$E$2)/(Thresholds!$F$2-Thresholds!$E$2))*0.279,MAX(0.02,0.2-((B15-Thresholds!$G$2)/(Thresholds!$H$2-Thresholds!$G$2))*0.18)))),3) -> 0.865 | J15: =ROUND(IF(C15<=Thresholds!$B$3,1-(C15/Thresholds!$B$3)*0.24,IF(C15<=Thresholds!$D$3,0.75-((C15-Thresholds!$C$3)/(Thresholds!$D$3-Thresholds!$C$3))*0.249,IF(C15<=Thresholds!$F$3,0.499-((C15-Thresholds!$E$3)/(Thresholds!$F$3-Thresholds!$E$3))*0.279,MAX(0.02,0.2-((C15-Thresholds!$G$3)/(Thresholds!$H$3-Thresholds!$G$3))*0.18)))),3) -> 0.531 | K15: =ROUND(IF(D15<=Thresholds!$B$4,1-(D15/Thresholds!$B$4)*0.24,IF(D15<=Thresholds!$D$4,0.75-((D15-Thresholds!$C$4)/(Thresholds!$D$4-Thresholds!$C$4))*0.249,IF(D15<=Thresholds!$F$4,0.499-((D15-Thresholds!$E$4)/(Thresholds!$F$4-Thresholds!$E$4))*0.279,MAX(0.02,0.2-((D15-Thresholds!$G$4)/(Thresholds!$H$4-Thresholds!$G$4))*0.18)))),3) -> 0.867 | L15: =ROUND(IF(E15<=Thresholds!$B$5,1-(E15/Thresholds!$B$5)*0.24,IF(E15<=Thresholds!$D$5,0.75-((E15-Thresholds!$C$5)/(Thresholds!$D$5-Thresholds!$C$5))*0.249,IF(E15<=Thresholds!$F$5,0.499-((E15-Thresholds!$E$5)/(Thresholds!$F$5-Thresholds!$E$5))*0.279,MAX(0.02,0.2-((E15-Thresholds!$G$5)/(Thresholds!$H$5-Thresholds!$G$5))*0.18)))),3) -> 0.988 | M15: =ROUND(IF(F15<=Thresholds!$B$6,1-(F15/Thresholds!$B$6)*0.24,IF(F15<=Thresholds!$D$6,0.75-((F15-Thresholds!$C$6)/(Thresholds!$D$6-Thresholds!$C$6))*0.249,IF(F15<=Thresholds!$F$6,0.499-((F15-Thresholds!$E$6)/(Thresholds!$F$6-Thresholds!$E$6))*0.279,MAX(0.02,0.2-((F15-Thresholds!$G$6)/(Thresholds!$H$6-Thresholds!$G$6))*0.18)))),3) -> 0.914 | N15: =ROUND(IF(G15<=Thresholds!$B$7,1-(G15/Thresholds!$B$7)*0.24,IF(G15<=Thresholds!$D$7,0.75-((G15-Thresholds!$C$7)/(Thresholds!$D$7-Thresholds!$C$7))*0.249,IF(G15<=Thresholds!$F$7,0.499-((G15-Thresholds!$E$7)/(Thresholds!$F$7-Thresholds!$E$7))*0.279,MAX(0.02,0.2-((G15-Thresholds!$G$7)/(Thresholds!$H$7-Thresholds!$G$7))*0.18)))),3) -> 0.984 | O15: =ROUND(IF(H15<=Thresholds!$B$8,1-(H15/Thresholds!$B$8)*0.24,IF(H15<=Thresholds!$D$8,0.75-((H15-Thresholds!$C$8)/(Thresholds!$D$8-Thresholds!$C$8))*0.249,IF(H15<=Thresholds!$F$8,0.499-((H15-Thresholds!$E$8)/(Thresholds!$F$8-Thresholds!$E$8))*0.279,MAX(0.02,0.2-((H15-Thresholds!$G$8)/(Thresholds!$H$8-Thresholds!$G$8))*0.18)))),3) -> 0.776 | P15: =ROUND(MIN(I15:O15),3) -> 0.531 | Q15: =IF(P15>=0.751,"Healthy",IF(P15>=0.501,"Moderate",IF(P15>=0.201,"Poor","Critical"))) -> Moderate | R15: =IF(P15>=0.5,1,0) -> 1 | S15: =IF(AND(F15>=10,F15<=35,P15>0.5),"ERROR_C15H15_POOR_CAP","OK") -> OK
A16: SYN-00015 | B16: 27.748 | C16: 33.459 | D16: 127.103 | E16: 6.241 | F16: 0.745 | G16: 288.828 | H16: 3920.326 | I16: =ROUND(IF(B16<=Thresholds!$B$2,1-(B16/Thresholds!$B$2)*0.24,IF(B16<=Thresholds!$D$2,0.75-((B16-Thresholds!$C$2)/(Thresholds!$D$2-Thresholds!$C$2))*0.249,IF(B16<=Thresholds!$F$2,0.499-((B16-Thresholds!$E$2)/(Thresholds!$F$2-Thresholds!$E$2))*0.279,MAX(0.02,0.2-((B16-Thresholds!$G$2)/(Thresholds!$H$2-Thresholds!$G$2))*0.18)))),3) -> 0.933 | J16: =ROUND(IF(C16<=Thresholds!$B$3,1-(C16/Thresholds!$B$3)*0.24,IF(C16<=Thresholds!$D$3,0.75-((C16-Thresholds!$C$3)/(Thresholds!$D$3-Thresholds!$C$3))*0.249,IF(C16<=Thresholds!$F$3,0.499-((C16-Thresholds!$E$3)/(Thresholds!$F$3-Thresholds!$E$3))*0.279,MAX(0.02,0.2-((C16-Thresholds!$G$3)/(Thresholds!$H$3-Thresholds!$G$3))*0.18)))),3) -> 0.933 | K16: =ROUND(IF(D16<=Thresholds!$B$4,1-(D16/Thresholds!$B$4)*0.24,IF(D16<=Thresholds!$D$4,0.75-((D16-Thresholds!$C$4)/(Thresholds!$D$4-Thresholds!$C$4))*0.249,IF(D16<=Thresholds!$F$4,0.499-((D16-Thresholds!$E$4)/(Thresholds!$F$4-Thresholds!$E$4))*0.279,MAX(0.02,0.2-((D16-Thresholds!$G$4)/(Thresholds!$H$4-Thresholds!$G$4))*0.18)))),3) -> 0.35 | L16: =ROUND(IF(E16<=Thresholds!$B$5,1-(E16/Thresholds!$B$5)*0.24,IF(E16<=Thresholds!$D$5,0.75-((E16-Thresholds!$C$5)/(Thresholds!$D$5-Thresholds!$C$5))*0.249,IF(E16<=Thresholds!$F$5,0.499-((E16-Thresholds!$E$5)/(Thresholds!$F$5-Thresholds!$E$5))*0.279,MAX(0.02,0.2-((E16-Thresholds!$G$5)/(Thresholds!$H$5-Thresholds!$G$5))*0.18)))),3) -> 0.97 | M16: =ROUND(IF(F16<=Thresholds!$B$6,1-(F16/Thresholds!$B$6)*0.24,IF(F16<=Thresholds!$D$6,0.75-((F16-Thresholds!$C$6)/(Thresholds!$D$6-Thresholds!$C$6))*0.249,IF(F16<=Thresholds!$F$6,0.499-((F16-Thresholds!$E$6)/(Thresholds!$F$6-Thresholds!$E$6))*0.279,MAX(0.02,0.2-((F16-Thresholds!$G$6)/(Thresholds!$H$6-Thresholds!$G$6))*0.18)))),3) -> 0.821 | N16: =ROUND(IF(G16<=Thresholds!$B$7,1-(G16/Thresholds!$B$7)*0.24,IF(G16<=Thresholds!$D$7,0.75-((G16-Thresholds!$C$7)/(Thresholds!$D$7-Thresholds!$C$7))*0.249,IF(G16<=Thresholds!$F$7,0.499-((G16-Thresholds!$E$7)/(Thresholds!$F$7-Thresholds!$E$7))*0.279,MAX(0.02,0.2-((G16-Thresholds!$G$7)/(Thresholds!$H$7-Thresholds!$G$7))*0.18)))),3) -> 0.802 | O16: =ROUND(IF(H16<=Thresholds!$B$8,1-(H16/Thresholds!$B$8)*0.24,IF(H16<=Thresholds!$D$8,0.75-((H16-Thresholds!$C$8)/(Thresholds!$D$8-Thresholds!$C$8))*0.249,IF(H16<=Thresholds!$F$8,0.499-((H16-Thresholds!$E$8)/(Thresholds!$F$8-Thresholds!$E$8))*0.279,MAX(0.02,0.2-((H16-Thresholds!$G$8)/(Thresholds!$H$8-Thresholds!$G$8))*0.18)))),3) -> 0.514 | P16: =ROUND(MIN(I16:O16),3) -> 0.35 | Q16: =IF(P16>=0.751,"Healthy",IF(P16>=0.501,"Moderate",IF(P16>=0.201,"Poor","Critical"))) -> Poor | R16: =IF(P16>=0.5,1,0) -> 0 | S16: =IF(AND(F16>=10,F16<=35,P16>0.5),"ERROR_C16H16_POOR_CAP","OK") -> OK
A17: SYN-00016 | B17: 30.18 | C17: 1312.405 | D17: 29.379 | E17: 12.56 | F17: 0.562 | G17: 260.202 | H17: 602.734 | I17: =ROUND(IF(B17<=Thresholds!$B$2,1-(B17/Thresholds!$B$2)*0.24,IF(B17<=Thresholds!$D$2,0.75-((B17-Thresholds!$C$2)/(Thresholds!$D$2-Thresholds!$C$2))*0.249,IF(B17<=Thresholds!$F$2,0.499-((B17-Thresholds!$E$2)/(Thresholds!$F$2-Thresholds!$E$2))*0.279,MAX(0.02,0.2-((B17-Thresholds!$G$2)/(Thresholds!$H$2-Thresholds!$G$2))*0.18)))),3) -> 0.928 | J17: =ROUND(IF(C17<=Thresholds!$B$3,1-(C17/Thresholds!$B$3)*0.24,IF(C17<=Thresholds!$D$3,0.75-((C17-Thresholds!$C$3)/(Thresholds!$D$3-Thresholds!$C$3))*0.249,IF(C17<=Thresholds!$F$3,0.499-((C17-Thresholds!$E$3)/(Thresholds!$F$3-Thresholds!$E$3))*0.279,MAX(0.02,0.2-((C17-Thresholds!$G$3)/(Thresholds!$H$3-Thresholds!$G$3))*0.18)))),3) -> 0.256 | K17: =ROUND(IF(D17<=Thresholds!$B$4,1-(D17/Thresholds!$B$4)*0.24,IF(D17<=Thresholds!$D$4,0.75-((D17-Thresholds!$C$4)/(Thresholds!$D$4-Thresholds!$C$4))*0.249,IF(D17<=Thresholds!$F$4,0.499-((D17-Thresholds!$E$4)/(Thresholds!$F$4-Thresholds!$E$4))*0.279,MAX(0.02,0.2-((D17-Thresholds!$G$4)/(Thresholds!$H$4-Thresholds!$G$4))*0.18)))),3) -> 0.892 | L17: =ROUND(IF(E17<=Thresholds!$B$5,1-(E17/Thresholds!$B$5)*0.24,IF(E17<=Thresholds!$D$5,0.75-((E17-Thresholds!$C$5)/(Thresholds!$D$5-Thresholds!$C$5))*0.249,IF(E17<=Thresholds!$F$5,0.499-((E17-Thresholds!$E$5)/(Thresholds!$F$5-Thresholds!$E$5))*0.279,MAX(0.02,0.2-((E17-Thresholds!$G$5)/(Thresholds!$H$5-Thresholds!$G$5))*0.18)))),3) -> 0.94 | M17: =ROUND(IF(F17<=Thresholds!$B$6,1-(F17/Thresholds!$B$6)*0.24,IF(F17<=Thresholds!$D$6,0.75-((F17-Thresholds!$C$6)/(Thresholds!$D$6-Thresholds!$C$6))*0.249,IF(F17<=Thresholds!$F$6,0.499-((F17-Thresholds!$E$6)/(Thresholds!$F$6-Thresholds!$E$6))*0.279,MAX(0.02,0.2-((F17-Thresholds!$G$6)/(Thresholds!$H$6-Thresholds!$G$6))*0.18)))),3) -> 0.865 | N17: =ROUND(IF(G17<=Thresholds!$B$7,1-(G17/Thresholds!$B$7)*0.24,IF(G17<=Thresholds!$D$7,0.75-((G17-Thresholds!$C$7)/(Thresholds!$D$7-Thresholds!$C$7))*0.249,IF(G17<=Thresholds!$F$7,0.499-((G17-Thresholds!$E$7)/(Thresholds!$F$7-Thresholds!$E$7))*0.279,MAX(0.02,0.2-((G17-Thresholds!$G$7)/(Thresholds!$H$7-Thresholds!$G$7))*0.18)))),3) -> 0.822 | O17: =ROUND(IF(H17<=Thresholds!$B$8,1-(H17/Thresholds!$B$8)*0.24,IF(H17<=Thresholds!$D$8,0.75-((H17-Thresholds!$C$8)/(Thresholds!$D$8-Thresholds!$C$8))*0.249,IF(H17<=Thresholds!$F$8,0.499-((H17-Thresholds!$E$8)/(Thresholds!$F$8-Thresholds!$E$8))*0.279,MAX(0.02,0.2-((H17-Thresholds!$G$8)/(Thresholds!$H$8-Thresholds!$G$8))*0.18)))),3) -> 0.942 | P17: =ROUND(MIN(I17:O17),3) -> 0.256 | Q17: =IF(P17>=0.751,"Healthy",IF(P17>=0.501,"Moderate",IF(P17>=0.201,"Poor","Critical"))) -> Poor | R17: =IF(P17>=0.5,1,0) -> 0 | S17: =IF(AND(F17>=10,F17<=35,P17>0.5),"ERROR_C17H17_POOR_CAP","OK") -> OK
A18: SYN-00017 | B18: 40.475 | C18: 108.556 | D18: 31.129 | E18: 14.276 | F18: 0.111 | G18: 24.494 | H18: 1440.564 | I18: =ROUND(IF(B18<=Thresholds!$B$2,1-(B18/Thresholds!$B$2)*0.24,IF(B18<=Thresholds!$D$2,0.75-((B18-Thresholds!$C$2)/(Thresholds!$D$2-Thresholds!$C$2))*0.249,IF(B18<=Thresholds!$F$2,0.499-((B18-Thresholds!$E$2)/(Thresholds!$F$2-Thresholds!$E$2))*0.279,MAX(0.02,0.2-((B18-Thresholds!$G$2)/(Thresholds!$H$2-Thresholds!$G$2))*0.18)))),3) -> 0.903 | J18: =ROUND(IF(C18<=Thresholds!$B$3,1-(C18/Thresholds!$B$3)*0.24,IF(C18<=Thresholds!$D$3,0.75-((C18-Thresholds!$C$3)/(Thresholds!$D$3-Thresholds!$C$3))*0.249,IF(C18<=Thresholds!$F$3,0.499-((C18-Thresholds!$E$3)/(Thresholds!$F$3-Thresholds!$E$3))*0.279,MAX(0.02,0.2-((C18-Thresholds!$G$3)/(Thresholds!$H$3-Thresholds!$G$3))*0.18)))),3) -> 0.783 | K18: =ROUND(IF(D18<=Thresholds!$B$4,1-(D18/Thresholds!$B$4)*0.24,IF(D18<=Thresholds!$D$4,0.75-((D18-Thresholds!$C$4)/(Thresholds!$D$4-Thresholds!$C$4))*0.249,IF(D18<=Thresholds!$F$4,0.499-((D18-Thresholds!$E$4)/(Thresholds!$F$4-Thresholds!$E$4))*0.279,MAX(0.02,0.2-((D18-Thresholds!$G$4)/(Thresholds!$H$4-Thresholds!$G$4))*0.18)))),3) -> 0.885 | L18: =ROUND(IF(E18<=Thresholds!$B$5,1-(E18/Thresholds!$B$5)*0.24,IF(E18<=Thresholds!$D$5,0.75-((E18-Thresholds!$C$5)/(Thresholds!$D$5-Thresholds!$C$5))*0.249,IF(E18<=Thresholds!$F$5,0.499-((E18-Thresholds!$E$5)/(Thresholds!$F$5-Thresholds!$E$5))*0.279,MAX(0.02,0.2-((E18-Thresholds!$G$5)/(Thresholds!$H$5-Thresholds!$G$5))*0.18)))),3) -> 0.931 | M18: =ROUND(IF(F18<=Thresholds!$B$6,1-(F18/Thresholds!$B$6)*0.24,IF(F18<=Thresholds!$D$6,0.75-((F18-Thresholds!$C$6)/(Thresholds!$D$6-Thresholds!$C$6))*0.249,IF(F18<=Thresholds!$F$6,0.499-((F18-Thresholds!$E$6)/(Thresholds!$F$6-Thresholds!$E$6))*0.279,MAX(0.02,0.2-((F18-Thresholds!$G$6)/(Thresholds!$H$6-Thresholds!$G$6))*0.18)))),3) -> 0.973 | N18: =ROUND(IF(G18<=Thresholds!$B$7,1-(G18/Thresholds!$B$7)*0.24,IF(G18<=Thresholds!$D$7,0.75-((G18-Thresholds!$C$7)/(Thresholds!$D$7-Thresholds!$C$7))*0.249,IF(G18<=Thresholds!$F$7,0.499-((G18-Thresholds!$E$7)/(Thresholds!$F$7-Thresholds!$E$7))*0.279,MAX(0.02,0.2-((G18-Thresholds!$G$7)/(Thresholds!$H$7-Thresholds!$G$7))*0.18)))),3) -> 0.983 | O18: =ROUND(IF(H18<=Thresholds!$B$8,1-(H18/Thresholds!$B$8)*0.24,IF(H18<=Thresholds!$D$8,0.75-((H18-Thresholds!$C$8)/(Thresholds!$D$8-Thresholds!$C$8))*0.249,IF(H18<=Thresholds!$F$8,0.499-((H18-Thresholds!$E$8)/(Thresholds!$F$8-Thresholds!$E$8))*0.279,MAX(0.02,0.2-((H18-Thresholds!$G$8)/(Thresholds!$H$8-Thresholds!$G$8))*0.18)))),3) -> 0.862 | P18: =ROUND(MIN(I18:O18),3) -> 0.783 | Q18: =IF(P18>=0.751,"Healthy",IF(P18>=0.501,"Moderate",IF(P18>=0.201,"Poor","Critical"))) -> Healthy | R18: =IF(P18>=0.5,1,0) -> 1 | S18: =IF(AND(F18>=10,F18<=35,P18>0.5),"ERROR_C18H18_POOR_CAP","OK") -> OK
A19: SYN-00018 | B19: 25.921 | C19: 14.093 | D19: 42.221 | E19: 13.375 | F19: 2.912 | G19: 303.329 | H19: 293.286 | I19: =ROUND(IF(B19<=Thresholds!$B$2,1-(B19/Thresholds!$B$2)*0.24,IF(B19<=Thresholds!$D$2,0.75-((B19-Thresholds!$C$2)/(Thresholds!$D$2-Thresholds!$C$2))*0.249,IF(B19<=Thresholds!$F$2,0.499-((B19-Thresholds!$E$2)/(Thresholds!$F$2-Thresholds!$E$2))*0.279,MAX(0.02,0.2-((B19-Thresholds!$G$2)/(Thresholds!$H$2-Thresholds!$G$2))*0.18)))),3) -> 0.938 | J19: =ROUND(IF(C19<=Thresholds!$B$3,1-(C19/Thresholds!$B$3)*0.24,IF(C19<=Thresholds!$D$3,0.75-((C19-Thresholds!$C$3)/(Thresholds!$D$3-Thresholds!$C$3))*0.249,IF(C19<=Thresholds!$F$3,0.499-((C19-Thresholds!$E$3)/(Thresholds!$F$3-Thresholds!$E$3))*0.279,MAX(0.02,0.2-((C19-Thresholds!$G$3)/(Thresholds!$H$3-Thresholds!$G$3))*0.18)))),3) -> 0.972 | K19: =ROUND(IF(D19<=Thresholds!$B$4,1-(D19/Thresholds!$B$4)*0.24,IF(D19<=Thresholds!$D$4,0.75-((D19-Thresholds!$C$4)/(Thresholds!$D$4-Thresholds!$C$4))*0.249,IF(D19<=Thresholds!$F$4,0.499-((D19-Thresholds!$E$4)/(Thresholds!$F$4-Thresholds!$E$4))*0.279,MAX(0.02,0.2-((D19-Thresholds!$G$4)/(Thresholds!$H$4-Thresholds!$G$4))*0.18)))),3) -> 0.844 | L19: =ROUND(IF(E19<=Thresholds!$B$5,1-(E19/Thresholds!$B$5)*0.24,IF(E19<=Thresholds!$D$5,0.75-((E19-Thresholds!$C$5)/(Thresholds!$D$5-Thresholds!$C$5))*0.249,IF(E19<=Thresholds!$F$5,0.499-((E19-Thresholds!$E$5)/(Thresholds!$F$5-Thresholds!$E$5))*0.279,MAX(0.02,0.2-((E19-Thresholds!$G$5)/(Thresholds!$H$5-Thresholds!$G$5))*0.18)))),3) -> 0.936 | M19: =ROUND(IF(F19<=Thresholds!$B$6,1-(F19/Thresholds!$B$6)*0.24,IF(F19<=Thresholds!$D$6,0.75-((F19-Thresholds!$C$6)/(Thresholds!$D$6-Thresholds!$C$6))*0.249,IF(F19<=Thresholds!$F$6,0.499-((F19-Thresholds!$E$6)/(Thresholds!$F$6-Thresholds!$E$6))*0.279,MAX(0.02,0.2-((F19-Thresholds!$G$6)/(Thresholds!$H$6-Thresholds!$G$6))*0.18)))),3) -> 0.691 | N19: =ROUND(IF(G19<=Thresholds!$B$7,1-(G19/Thresholds!$B$7)*0.24,IF(G19<=Thresholds!$D$7,0.75-((G19-Thresholds!$C$7)/(Thresholds!$D$7-Thresholds!$C$7))*0.249,IF(G19<=Thresholds!$F$7,0.499-((G19-Thresholds!$E$7)/(Thresholds!$F$7-Thresholds!$E$7))*0.279,MAX(0.02,0.2-((G19-Thresholds!$G$7)/(Thresholds!$H$7-Thresholds!$G$7))*0.18)))),3) -> 0.792 | O19: =ROUND(IF(H19<=Thresholds!$B$8,1-(H19/Thresholds!$B$8)*0.24,IF(H19<=Thresholds!$D$8,0.75-((H19-Thresholds!$C$8)/(Thresholds!$D$8-Thresholds!$C$8))*0.249,IF(H19<=Thresholds!$F$8,0.499-((H19-Thresholds!$E$8)/(Thresholds!$F$8-Thresholds!$E$8))*0.279,MAX(0.02,0.2-((H19-Thresholds!$G$8)/(Thresholds!$H$8-Thresholds!$G$8))*0.18)))),3) -> 0.972 | P19: =ROUND(MIN(I19:O19),3) -> 0.691 | Q19: =IF(P19>=0.751,"Healthy",IF(P19>=0.501,"Moderate",IF(P19>=0.201,"Poor","Critical"))) -> Moderate | R19: =IF(P19>=0.5,1,0) -> 1 | S19: =IF(AND(F19>=10,F19<=35,P19>0.5),"ERROR_C19H19_POOR_CAP","OK") -> OK
A20: SYN-00019 | B20: 56.227 | C20: 457.501 | D20: 57.737 | E20: 29.87 | F20: 0.281 | G20: 174.764 | H20: 1091.767 | I20: =ROUND(IF(B20<=Thresholds!$B$2,1-(B20/Thresholds!$B$2)*0.24,IF(B20<=Thresholds!$D$2,0.75-((B20-Thresholds!$C$2)/(Thresholds!$D$2-Thresholds!$C$2))*0.249,IF(B20<=Thresholds!$F$2,0.499-((B20-Thresholds!$E$2)/(Thresholds!$F$2-Thresholds!$E$2))*0.279,MAX(0.02,0.2-((B20-Thresholds!$G$2)/(Thresholds!$H$2-Thresholds!$G$2))*0.18)))),3) -> 0.865 | J20: =ROUND(IF(C20<=Thresholds!$B$3,1-(C20/Thresholds!$B$3)*0.24,IF(C20<=Thresholds!$D$3,0.75-((C20-Thresholds!$C$3)/(Thresholds!$D$3-Thresholds!$C$3))*0.249,IF(C20<=Thresholds!$F$3,0.499-((C20-Thresholds!$E$3)/(Thresholds!$F$3-Thresholds!$E$3))*0.279,MAX(0.02,0.2-((C20-Thresholds!$G$3)/(Thresholds!$H$3-Thresholds!$G$3))*0.18)))),3) -> 0.473 | K20: =ROUND(IF(D20<=Thresholds!$B$4,1-(D20/Thresholds!$B$4)*0.24,IF(D20<=Thresholds!$D$4,0.75-((D20-Thresholds!$C$4)/(Thresholds!$D$4-Thresholds!$C$4))*0.249,IF(D20<=Thresholds!$F$4,0.499-((D20-Thresholds!$E$4)/(Thresholds!$F$4-Thresholds!$E$4))*0.279,MAX(0.02,0.2-((D20-Thresholds!$G$4)/(Thresholds!$H$4-Thresholds!$G$4))*0.18)))),3) -> 0.787 | L20: =ROUND(IF(E20<=Thresholds!$B$5,1-(E20/Thresholds!$B$5)*0.24,IF(E20<=Thresholds!$D$5,0.75-((E20-Thresholds!$C$5)/(Thresholds!$D$5-Thresholds!$C$5))*0.249,IF(E20<=Thresholds!$F$5,0.499-((E20-Thresholds!$E$5)/(Thresholds!$F$5-Thresholds!$E$5))*0.279,MAX(0.02,0.2-((E20-Thresholds!$G$5)/(Thresholds!$H$5-Thresholds!$G$5))*0.18)))),3) -> 0.857 | M20: =ROUND(IF(F20<=Thresholds!$B$6,1-(F20/Thresholds!$B$6)*0.24,IF(F20<=Thresholds!$D$6,0.75-((F20-Thresholds!$C$6)/(Thresholds!$D$6-Thresholds!$C$6))*0.249,IF(F20<=Thresholds!$F$6,0.499-((F20-Thresholds!$E$6)/(Thresholds!$F$6-Thresholds!$E$6))*0.279,MAX(0.02,0.2-((F20-Thresholds!$G$6)/(Thresholds!$H$6-Thresholds!$G$6))*0.18)))),3) -> 0.933 | N20: =ROUND(IF(G20<=Thresholds!$B$7,1-(G20/Thresholds!$B$7)*0.24,IF(G20<=Thresholds!$D$7,0.75-((G20-Thresholds!$C$7)/(Thresholds!$D$7-Thresholds!$C$7))*0.249,IF(G20<=Thresholds!$F$7,0.499-((G20-Thresholds!$E$7)/(Thresholds!$F$7-Thresholds!$E$7))*0.279,MAX(0.02,0.2-((G20-Thresholds!$G$7)/(Thresholds!$H$7-Thresholds!$G$7))*0.18)))),3) -> 0.88 | O20: =ROUND(IF(H20<=Thresholds!$B$8,1-(H20/Thresholds!$B$8)*0.24,IF(H20<=Thresholds!$D$8,0.75-((H20-Thresholds!$C$8)/(Thresholds!$D$8-Thresholds!$C$8))*0.249,IF(H20<=Thresholds!$F$8,0.499-((H20-Thresholds!$E$8)/(Thresholds!$F$8-Thresholds!$E$8))*0.279,MAX(0.02,0.2-((H20-Thresholds!$G$8)/(Thresholds!$H$8-Thresholds!$G$8))*0.18)))),3) -> 0.895 | P20: =ROUND(MIN(I20:O20),3) -> 0.473 | Q20: =IF(P20>=0.751,"Healthy",IF(P20>=0.501,"Moderate",IF(P20>=0.201,"Poor","Critical"))) -> Poor | R20: =IF(P20>=0.5,1,0) -> 0 | S20: =IF(AND(F20>=10,F20<=35,P20>0.5),"ERROR_C20H20_POOR_CAP","OK") -> OK
A21: SYN-00020 | B21: 45.24 | C21: 59.241 | D21: 201.556 | E21: 34.485 | F21: 0.985 | G21: 50.224 | H21: 1081.226 | I21: =ROUND(IF(B21<=Thresholds!$B$2,1-(B21/Thresholds!$B$2)*0.24,IF(B21<=Thresholds!$D$2,0.75-((B21-Thresholds!$C$2)/(Thresholds!$D$2-Thresholds!$C$2))*0.249,IF(B21<=Thresholds!$F$2,0.499-((B21-Thresholds!$E$2)/(Thresholds!$F$2-Thresholds!$E$2))*0.279,MAX(0.02,0.2-((B21-Thresholds!$G$2)/(Thresholds!$H$2-Thresholds!$G$2))*0.18)))),3) -> 0.891 | J21: =ROUND(IF(C21<=Thresholds!$B$3,1-(C21/Thresholds!$B$3)*0.24,IF(C21<=Thresholds!$D$3,0.75-((C21-Thresholds!$C$3)/(Thresholds!$D$3-Thresholds!$C$3))*0.249,IF(C21<=Thresholds!$F$3,0.499-((C21-Thresholds!$E$3)/(Thresholds!$F$3-Thresholds!$E$3))*0.279,MAX(0.02,0.2-((C21-Thresholds!$G$3)/(Thresholds!$H$3-Thresholds!$G$3))*0.18)))),3) -> 0.882 | K21: =ROUND(IF(D21<=Thresholds!$B$4,1-(D21/Thresholds!$B$4)*0.24,IF(D21<=Thresholds!$D$4,0.75-((D21-Thresholds!$C$4)/(Thresholds!$D$4-Thresholds!$C$4))*0.249,IF(D21<=Thresholds!$F$4,0.499-((D21-Thresholds!$E$4)/(Thresholds!$F$4-Thresholds!$E$4))*0.279,MAX(0.02,0.2-((D21-Thresholds!$G$4)/(Thresholds!$H$4-Thresholds!$G$4))*0.18)))),3) -> 0.26 | L21: =ROUND(IF(E21<=Thresholds!$B$5,1-(E21/Thresholds!$B$5)*0.24,IF(E21<=Thresholds!$D$5,0.75-((E21-Thresholds!$C$5)/(Thresholds!$D$5-Thresholds!$C$5))*0.249,IF(E21<=Thresholds!$F$5,0.499-((E21-Thresholds!$E$5)/(Thresholds!$F$5-Thresholds!$E$5))*0.279,MAX(0.02,0.2-((E21-Thresholds!$G$5)/(Thresholds!$H$5-Thresholds!$G$5))*0.18)))),3) -> 0.834 | M21: =ROUND(IF(F21<=Thresholds!$B$6,1-(F21/Thresholds!$B$6)*0.24,IF(F21<=Thresholds!$D$6,0.75-((F21-Thresholds!$C$6)/(Thresholds!$D$6-Thresholds!$C$6))*0.249,IF(F21<=Thresholds!$F$6,0.499-((F21-Thresholds!$E$6)/(Thresholds!$F$6-Thresholds!$E$6))*0.279,MAX(0.02,0.2-((F21-Thresholds!$G$6)/(Thresholds!$H$6-Thresholds!$G$6))*0.18)))),3) -> 0.764 | N21: =ROUND(IF(G21<=Thresholds!$B$7,1-(G21/Thresholds!$B$7)*0.24,IF(G21<=Thresholds!$D$7,0.75-((G21-Thresholds!$C$7)/(Thresholds!$D$7-Thresholds!$C$7))*0.249,IF(G21<=Thresholds!$F$7,0.499-((G21-Thresholds!$E$7)/(Thresholds!$F$7-Thresholds!$E$7))*0.279,MAX(0.02,0.2-((G21-Thresholds!$G$7)/(Thresholds!$H$7-Thresholds!$G$7))*0.18)))),3) -> 0.966 | O21: =ROUND(IF(H21<=Thresholds!$B$8,1-(H21/Thresholds!$B$8)*0.24,IF(H21<=Thresholds!$D$8,0.75-((H21-Thresholds!$C$8)/(Thresholds!$D$8-Thresholds!$C$8))*0.249,IF(H21<=Thresholds!$F$8,0.499-((H21-Thresholds!$E$8)/(Thresholds!$F$8-Thresholds!$E$8))*0.279,MAX(0.02,0.2-((H21-Thresholds!$G$8)/(Thresholds!$H$8-Thresholds!$G$8))*0.18)))),3) -> 0.896 | P21: =ROUND(MIN(I21:O21),3) -> 0.26 | Q21: =IF(P21>=0.751,"Healthy",IF(P21>=0.501,"Moderate",IF(P21>=0.201,"Poor","Critical"))) -> Poor | R21: =IF(P21>=0.5,1,0) -> 0 | S21: =IF(AND(F21>=10,F21<=35,P21>0.5),"ERROR_C21H21_POOR_CAP","OK") -> OK
A22: SYN-00021 | B22: 23.201 | C22: 67.137 | D22: 11.906 | E22: 11.216 | F22: 0.489 | G22: 308.267 | H22: 304.039 | I22: =ROUND(IF(B22<=Thresholds!$B$2,1-(B22/Thresholds!$B$2)*0.24,IF(B22<=Thresholds!$D$2,0.75-((B22-Thresholds!$C$2)/(Thresholds!$D$2-Thresholds!$C$2))*0.249,IF(B22<=Thresholds!$F$2,0.499-((B22-Thresholds!$E$2)/(Thresholds!$F$2-Thresholds!$E$2))*0.279,MAX(0.02,0.2-((B22-Thresholds!$G$2)/(Thresholds!$H$2-Thresholds!$G$2))*0.18)))),3) -> 0.944 | J22: =ROUND(IF(C22<=Thresholds!$B$3,1-(C22/Thresholds!$B$3)*0.24,IF(C22<=Thresholds!$D$3,0.75-((C22-Thresholds!$C$3)/(Thresholds!$D$3-Thresholds!$C$3))*0.249,IF(C22<=Thresholds!$F$3,0.499-((C22-Thresholds!$E$3)/(Thresholds!$F$3-Thresholds!$E$3))*0.279,MAX(0.02,0.2-((C22-Thresholds!$G$3)/(Thresholds!$H$3-Thresholds!$G$3))*0.18)))),3) -> 0.866 | K22: =ROUND(IF(D22<=Thresholds!$B$4,1-(D22/Thresholds!$B$4)*0.24,IF(D22<=Thresholds!$D$4,0.75-((D22-Thresholds!$C$4)/(Thresholds!$D$4-Thresholds!$C$4))*0.249,IF(D22<=Thresholds!$F$4,0.499-((D22-Thresholds!$E$4)/(Thresholds!$F$4-Thresholds!$E$4))*0.279,MAX(0.02,0.2-((D22-Thresholds!$G$4)/(Thresholds!$H$4-Thresholds!$G$4))*0.18)))),3) -> 0.956 | L22: =ROUND(IF(E22<=Thresholds!$B$5,1-(E22/Thresholds!$B$5)*0.24,IF(E22<=Thresholds!$D$5,0.75-((E22-Thresholds!$C$5)/(Thresholds!$D$5-Thresholds!$C$5))*0.249,IF(E22<=Thresholds!$F$5,0.499-((E22-Thresholds!$E$5)/(Thresholds!$F$5-Thresholds!$E$5))*0.279,MAX(0.02,0.2-((E22-Thresholds!$G$5)/(Thresholds!$H$5-Thresholds!$G$5))*0.18)))),3) -> 0.946 | M22: =ROUND(IF(F22<=Thresholds!$B$6,1-(F22/Thresholds!$B$6)*0.24,IF(F22<=Thresholds!$D$6,0.75-((F22-Thresholds!$C$6)/(Thresholds!$D$6-Thresholds!$C$6))*0.249,IF(F22<=Thresholds!$F$6,0.499-((F22-Thresholds!$E$6)/(Thresholds!$F$6-Thresholds!$E$6))*0.279,MAX(0.02,0.2-((F22-Thresholds!$G$6)/(Thresholds!$H$6-Thresholds!$G$6))*0.18)))),3) -> 0.883 | N22: =ROUND(IF(G22<=Thresholds!$B$7,1-(G22/Thresholds!$B$7)*0.24,IF(G22<=Thresholds!$D$7,0.75-((G22-Thresholds!$C$7)/(Thresholds!$D$7-Thresholds!$C$7))*0.249,IF(G22<=Thresholds!$F$7,0.499-((G22-Thresholds!$E$7)/(Thresholds!$F$7-Thresholds!$E$7))*0.279,MAX(0.02,0.2-((G22-Thresholds!$G$7)/(Thresholds!$H$7-Thresholds!$G$7))*0.18)))),3) -> 0.789 | O22: =ROUND(IF(H22<=Thresholds!$B$8,1-(H22/Thresholds!$B$8)*0.24,IF(H22<=Thresholds!$D$8,0.75-((H22-Thresholds!$C$8)/(Thresholds!$D$8-Thresholds!$C$8))*0.249,IF(H22<=Thresholds!$F$8,0.499-((H22-Thresholds!$E$8)/(Thresholds!$F$8-Thresholds!$E$8))*0.279,MAX(0.02,0.2-((H22-Thresholds!$G$8)/(Thresholds!$H$8-Thresholds!$G$8))*0.18)))),3) -> 0.971 | P22: =ROUND(MIN(I22:O22),3) -> 0.789 | Q22: =IF(P22>=0.751,"Healthy",IF(P22>=0.501,"Moderate",IF(P22>=0.201,"Poor","Critical"))) -> Healthy | R22: =IF(P22>=0.5,1,0) -> 1 | S22: =IF(AND(F22>=10,F22<=35,P22>0.5),"ERROR_C22H22_POOR_CAP","OK") -> OK
